
<mujoco model="irb120">
	<compiler inertiafromgeom='true' angle="radian" settotalmass="25.5" meshdir="stl/" />


  	<option timestep="0.002" gravity="0 0 -9.81"/>


  	<asset>
        <mesh name="base" file="base.stl" scale="0.001 0.001 0.001"/>
        <mesh name="link1" file="link1.stl" scale="0.001 0.001 0.001"/>
        <mesh name="link2" file="link2.stl" scale="0.001 0.001 0.001"/>
        <mesh name="link3" file="link3.stl" scale="0.001 0.001 0.001"/>
        <mesh name="link4" file="link4.stl" scale="0.001 0.001 0.001"/>
        <mesh name="link5" file="link5.stl" scale="0.001 0.001 0.001"/>
        <mesh name="link6" file="link6.stl" scale="0.001 0.001 0.001"/>
        <mesh name="connection_part" file="connection_part.stl" scale="0.001 0.001 0.001"/>
        <mesh name="gripper_left" file="gripper_left.stl" scale="0.001 0.001 0.001"/>
        <mesh name="gripper_right" file="gripper_right.stl" scale="0.001 0.001 0.001"/>
        <mesh name="schunk" file="schunk.stl" scale="0.001 0.001 0.001"/>
		<texture type="skybox" builtin="gradient" rgb1=".2 .3 .4" rgb2="1 1 1" width="100" height="100"/>
		<texture name="groundplane" type="2d" builtin="checker" rgb1=".25 .26 .25" rgb2=".22 .22 .22" width="100" height="100" mark="none" markrgb=".8 .8 .8"/>
		<texture name="greenground" type="2d" builtin="gradient" rgb1="0.19 0.28 0.23" rgb2="0 0 0" width="100" height="100" mark="none" markrgb=".8 .8 .8"/>
		<material name="MatViz" specular="1" shininess=".1" reflectance="0.5" rgba=".07 .07 .1 1"/>
		<material name="MatGnd" texture="groundplane"  texrepeat="5 5" specular="1" shininess="0" reflectance="0"/>
  	</asset>


  	<contact>
		<pair geom1 = "geo_link1" geom2 = "geo_base" condim= "1"/>
  	</contact>


	<default class="robot0:fetch">
		<joint armature="0" damping="10" frictionloss="0" stiffness="0"></joint>
		<default class="robot0:fetchGripper">
			<joint armature="0" damping="50" limited="true" solimplimit="0.9 0.999 0.01" solreflimit="0.01 1" type="slide"></joint>
		</default>
	</default>
	
	
	<default class ="ground">
		<geom type="plane" margin="0.001" contype="1" />
	</default>


	<worldbody>
	    <light cutoff="200" diffuse="1.2 1.2 1.2" dir="-0 0 -1.3" directional="true" exponent="1" pos="0 0 1.3" specular=".1 .1 .1" castshadow="true"/>

	    <camera name="view1" pos="0.2 0.1 2.0" zaxis="0 0 1" fovy="45" ipd="0.068"/>

	    <geom name="ground" class="ground" type='plane' pos="0 0 0" rgba="0.19 0.30 0.23 1" size="2 2 1"/>
	        <body name="robot0:base_link" pos="0 0 0" axisangle="1 0 0 1.57079632679">
	        <geom name = "geo_base" pos = "0.0 0.0 0.0" type="mesh" rgba="1 0.5 0 1" mesh="base" />
	        <body name="link1" pos= "0 0 0">
	            <joint name="joint0" axis="0 1 0" range = "-2.879 2.879" limited="true"/>
	            <geom name = "geo_link1" pos = "0.0 0.0 0.0" type="mesh" rgba="1 0.5 0 1" mesh="link1" />
	            <body name="link2" pos="0 0 0"> 
	                <joint name="joint1" axis="0 0 -1" range = "-1.91986 1.91986" limited="true" pos="0 0.290 0" />
	                <geom name = "geo_link2" pos="0 0.560 0.058" type="mesh" rgba="1 0.5 0 1" mesh="link2" />
	                <body name="link3" pos="0 0 0" >  
	                    <joint name="joint2" axis="0 0 -1" range = "-1.91986 1.22173" limited="true" pos="0 0.560 1" />
	                    <geom name = "geo_link3" pos="0.07195 0.49385 0 " type="mesh" rgba="1 0.5 0 1" mesh="link3" />
	                    <body name="link4" pos = "0 0 0"> 
	                        <joint name="joint3" axis="1 0 0" range = "-2.79 2.79" limited="true" pos="0.134  0.630  0" />
	                        <geom name = "geo_link4" pos="0.302 0.630 0 " type="mesh" rgba="1 0.5 0 1" mesh="link4"/>
	                        <body name="link5" pos = "0 0 0">
	                            <joint name="joint4" axis="0 0 -1"  range = "-2.0944 2.0944" limited="true" pos="0.302 0.630 0"/>
	                            <geom name = "geo_link5" pos="0 0 0" type="mesh" rgba="1 0.5 0 1" mesh="link5" />
	                            <body name="link6" pos ="0 0 0"> 
	                                <joint name="joint5" axis="1 0 0"  range = "-4.22 4.22" limited="true" pos="0.361 0.630 0"/> 
	                                <geom name = "geo_link6" pos="0.361 0.630 0" axisangle="0 1 0 1.57079632679" type="mesh" rgba="0 0 0 1" mesh="link6" />
	                                <body name="connection_part" pos ="0 0 0">
	                                    <geom name = "geo_connection_part" pos="0.38887 0.630 0" quat="0.5 0.5 -0.5 0.5" type="mesh" rgba="0.67 0.67 0.67 1" mesh="connection_part" />
	                                    
	                                    <body name="robot0:gripper_link" pos="0.40296 0.64122 0" >
	                                        <geom type="mesh" mesh="schunk" name="robot0:gripper_link" rgba="1 1 0 1" quat="0.71 0 0.71 0"></geom>
									
	        <body childclass="robot0:fetchGripper" name="robot0:r_gripper_finger_link" pos="-0.0065 -0.06 -0.031">
	            <joint axis="0 0 1" name="robot0:r_gripper_finger_joint" range="0 0.05"></joint>
	            <geom type="mesh" mesh="gripper_right" rgba="1 1 1 1" name="geo_gripper_right" quat="0 0.71 0 0.71"></geom>
	        </body>
	        <body childclass="robot0:fetchGripper" name="robot0:l_gripper_finger_link" pos="-0.0065 -0.06 0.031">
	            <joint axis="0 0 -1" name="robot0:l_gripper_finger_joint" range="0 0.05"></joint>
	            <geom type="mesh" mesh="gripper_left" rgba="1 1 1 1" name="geo_gripper_left" quat="0 0.71 0 0.71"></geom>
	        </body>
	        
	        <site name="robot0:grip" pos="0.06 -0.06 0" rgba="0.5 0.5 0.5 0" size="0.01 0.01 0.01"></site>
	        
	                                    </body>
	                                </body>
	                            </body>
	                        </body>
	                    </body>
	                </body>
	            </body>
	        </body>
	        </body>
	        
	        <geom name="target" pos="0.2 0 0.03" rgba="0.9 0.1 0.1 1" size="0.03 0.03 0.03" type="box" contype='0' conaffinity="0"/>
	</worldbody>
	
	<actuator>        
		<position ctrlrange="-2.879 2.879" ctrllimited="true" name="joint0_motor" joint="joint0"/>
		<position ctrlrange="-1.91986 1.91986" ctrllimited="true" name="joint1_motor" joint="joint1"/>
		<position ctrlrange="-1.91986 1.22173" ctrllimited="true" name="joint2_motor" joint="joint2"/>
		<position ctrlrange="-2.79 2.79" ctrllimited="true" name="joint3_motor" joint="joint3"/>
		<position ctrlrange="-2.0944 2.0944" ctrllimited="true" name="joint4_motor" joint="joint4"/>
		<position ctrlrange="-4.22 4.22" ctrllimited="true" name="joint5_motor" joint="joint5"/>
	</actuator>
	
</mujoco>
